// PROBLEM: Empty catch block
// FIX: Rename 'ex' to '_'
fun test() {
    try {
        test1()
    }
    catch(_: Exception) {
    }

}
fun test1() {}
